<?xml version="1.0" encoding="utf-8"?>

<mujoco model="dual ur3 larr (left arm)">

    <body name="left_base_link" pos="0 0 0" euler ="0 0 1.570796"> <!--no angle--> <!--euler ="0 0 1.570796"-->
        <inertial pos="0 0 0" quat="0.5 0.5 -0.5 0.5" mass="2" diaginertia="0.005625 0.00305317 0.00305317" />
        <geom type="mesh" pos = "0 0 -0.005" rgba="0.7 0.7 0.7 1" mesh="ur_base" material="robot0:base_mat" />
        
        <body name="left_shoulder_link" pos="0 0 0.1519">
            <inertial pos="0 0 0" mass="2" diaginertia="0.00809316 0.00809316 0.005625" />
            <joint name="left_shoulder_pan_joint" pos="0 0 0" axis="0 0 1" limited="true" range="-6.28319 6.28319" damping="10"/>
            <geom type="mesh" rgba="0.7 0.7 0.7 1" mesh="shoulder" material="robot0:head_mat" />
            <body name="left_upper_arm_link" pos="0 0.1198 0" quat="0.707107 0 0.707107 0" ><!--quat="0.707107 0 0.707107 0"-->
                <inertial pos="0 0 0.121825" mass="3.42" diaginertia="0.0217285 0.0217285 0.00961875" />
                <joint name="left_shoulder_lift_joint" pos="0 0 0" axis="0 1 0" limited="true" range="-6.28319 6.28319" damping="10"/>
                <geom type="mesh" rgba="0.7 0.7 0.7 1" mesh="upperarm" material="robot0:head_mat" />
                <body name="left_forearm_link" pos="0 -0.0925 0.24365"> <!--no angle--><!-- euler="0 1.570796 0"-->
                    <inertial pos="0 0 0.106625" mass="1.26" diaginertia="0.00654681 0.00654681 0.00354375" />
                    <joint name="left_elbow_joint" pos="0 0 0" axis="0 1 0" limited="true" range="-3.14159 3.14159" damping="10"/>
                    <geom type="mesh" rgba="0.7 0.7 0.7 1" mesh="forearm" material="robot0:arm_mat"/>
                    <body name="left_wrist_1_link" pos="0 0 0.21325" quat="0.707107 0 0.707107 0" ><!--quat="0.707107 0 0.707107 0"-->
                        <inertial pos="0 0 0" quat="0.5 0.5 -0.5 0.5" mass="0.8" diaginertia="0.00225 0.002085 0.002085" />
                        <joint name="left_wrist_1_joint" pos="0 0 0" axis="0 1 0" limited="true" range="-6.28319 6.28319" damping="10"/>
                        <geom type="mesh" rgba="0.7 0.7 0.7 1" mesh="wrist1" material="RobMat"/>
                        <body name="left_wrist_2_link" pos="0 0.08505 0"> <!--no angle--> <!-- euler ="0 0 -1.570796"-->
                            <inertial pos="0 0 0" quat="0.5 0.5 -0.5 0.5" mass="0.8" diaginertia="0.00225 0.002085 0.002085" />
                            <joint name="left_wrist_2_joint" pos="0 0 0" axis="0 0 1" limited="true" range="-6.28319 6.28319" damping="10"/>
                            <geom type="mesh" rgba="0.7 0.7 0.7 1" mesh="wrist2" material="RobMat" />
                            <body name="left_wrist_3_link" pos="0 0 0.08535">
                                <inertial pos="0 0 0" quat="0.5 0.5 -0.5 0.5" mass="0.35" diaginertia="0.000984375 0.000912187 0.000912187" />
                                <joint name="left_wrist_3_joint" pos="0 0 0" axis="0 1 0" limited="true" range="-6.28319 6.28319" damping="10"/>
                                <geom type="mesh" rgba="0.7 0.7 0.7 1" mesh="wrist3" material="RobMat"/>
                                
                                <body name="left_ee_link" pos="0 0.0819 0" euler = "-1.570796 0 0"> <!--name was ee_link--> <!--euler = "-1.570796 0 0"-->
                                    <!--Import Robotiq 2F-85 Gripper-->
                                    <!-- <include file="robotiq85_gripper.xml"/>  -->
                                </body>

                            </body>
                        </body>
                    </body>
                </body>
            </body>
        </body>

        <body name="left_ur3_base" pos="0 0 0" quat="1.7949e-09 0 0 -1">
            <inertial pos="0 0 0" quat="1.7949e-09 0 0 -1" mass="0" diaginertia="0 0 0" />
        </body>
    </body>

</mujoco>